{"timestamp":"2025-05-28T01:26:16.543770","level":"info","event":"DAG bundles loaded: dags-folder","logger":"airflow.dag_processing.bundles.manager.DagBundlesManager"}
{"timestamp":"2025-05-28T01:26:16.544322","level":"info","event":"Filling up the DagBag from /home/ubuntu/airflow/dags/sentiment_fetch_dag.py","logger":"airflow.models.dagbag.DagBag"}
{"timestamp":"2025-05-28T01:26:16.704686","level":"info","event":"POST http://localhost:9200/news_raw/_doc [status:N/A duration:0.001s]","logger":"elastic_transport.transport"}
{"timestamp":"2025-05-28T01:26:16.704791","level":"warning","event":"Node <Urllib3HttpNode(http://localhost:9200)> has failed for 1 times in a row, putting on 1 second timeout","logger":"elastic_transport.node_pool"}
{"timestamp":"2025-05-28T01:26:16.704885","level":"warning","event":"Retrying request after failure (attempt 0 of 3)","logger":"elastic_transport.transport","error_detail":[{"exc_type":"ConnectionError","exc_value":"Connection error caused by: NewConnectionError(<urllib3.connection.HTTPConnection object at 0x75beadee08c0>: Failed to establish a new connection: [Errno 111] Connection refused)","exc_notes":[],"syntax_error":null,"is_cause":false,"frames":[{"filename":"/home/ubuntu/airflow_venv/lib/python3.12/site-packages/elastic_transport/_transport.py","lineno":342,"name":"perform_request"},{"filename":"/home/ubuntu/airflow_venv/lib/python3.12/site-packages/elastic_transport/_node/_http_urllib3.py","lineno":202,"name":"perform_request"}]},{"exc_type":"NewConnectionError","exc_value":"<urllib3.connection.HTTPConnection object at 0x75beadee08c0>: Failed to establish a new connection: [Errno 111] Connection refused","exc_notes":[],"syntax_error":null,"is_cause":true,"frames":[{"filename":"/home/ubuntu/airflow_venv/lib/python3.12/site-packages/elastic_transport/_node/_http_urllib3.py","lineno":167,"name":"perform_request"},{"filename":"/home/ubuntu/airflow_venv/lib/python3.12/site-packages/urllib3/connectionpool.py","lineno":841,"name":"urlopen"},{"filename":"/home/ubuntu/airflow_venv/lib/python3.12/site-packages/urllib3/util/retry.py","lineno":449,"name":"increment"},{"filename":"/home/ubuntu/airflow_venv/lib/python3.12/site-packages/urllib3/util/util.py","lineno":39,"name":"reraise"},{"filename":"/home/ubuntu/airflow_venv/lib/python3.12/site-packages/urllib3/connectionpool.py","lineno":787,"name":"urlopen"},{"filename":"/home/ubuntu/airflow_venv/lib/python3.12/site-packages/urllib3/connectionpool.py","lineno":493,"name":"_make_request"},{"filename":"/home/ubuntu/airflow_venv/lib/python3.12/site-packages/urllib3/connection.py","lineno":445,"name":"request"},{"filename":"/usr/lib/python3.12/http/client.py","lineno":1331,"name":"endheaders"},{"filename":"/usr/lib/python3.12/http/client.py","lineno":1091,"name":"_send_output"},{"filename":"/usr/lib/python3.12/http/client.py","lineno":1035,"name":"send"},{"filename":"/home/ubuntu/airflow_venv/lib/python3.12/site-packages/urllib3/connection.py","lineno":276,"name":"connect"},{"filename":"/home/ubuntu/airflow_venv/lib/python3.12/site-packages/urllib3/connection.py","lineno":213,"name":"_new_conn"}]},{"exc_type":"ConnectionRefusedError","exc_value":"[Errno 111] Connection refused","exc_notes":[],"syntax_error":null,"is_cause":true,"frames":[{"filename":"/home/ubuntu/airflow_venv/lib/python3.12/site-packages/urllib3/connection.py","lineno":198,"name":"_new_conn"},{"filename":"/home/ubuntu/airflow_venv/lib/python3.12/site-packages/urllib3/util/connection.py","lineno":85,"name":"create_connection"},{"filename":"/home/ubuntu/airflow_venv/lib/python3.12/site-packages/urllib3/util/connection.py","lineno":73,"name":"create_connection"}]}]}
{"timestamp":"2025-05-28T01:26:16.705485","level":"info","event":"POST http://localhost:9200/news_raw/_doc [status:N/A duration:0.000s]","logger":"elastic_transport.transport"}
{"timestamp":"2025-05-28T01:26:16.705579","level":"warning","event":"Node <Urllib3HttpNode(http://localhost:9200)> has failed for 2 times in a row, putting on 2 second timeout","logger":"elastic_transport.node_pool"}
{"timestamp":"2025-05-28T01:26:16.705655","level":"warning","event":"Retrying request after failure (attempt 1 of 3)","logger":"elastic_transport.transport","error_detail":[{"exc_type":"ConnectionError","exc_value":"Connection error caused by: NewConnectionError(<urllib3.connection.HTTPConnection object at 0x75beadee0d40>: Failed to establish a new connection: [Errno 111] Connection refused)","exc_notes":[],"syntax_error":null,"is_cause":false,"frames":[{"filename":"/home/ubuntu/airflow_venv/lib/python3.12/site-packages/elastic_transport/_transport.py","lineno":342,"name":"perform_request"},{"filename":"/home/ubuntu/airflow_venv/lib/python3.12/site-packages/elastic_transport/_node/_http_urllib3.py","lineno":202,"name":"perform_request"}]},{"exc_type":"NewConnectionError","exc_value":"<urllib3.connection.HTTPConnection object at 0x75beadee0d40>: Failed to establish a new connection: [Errno 111] Connection refused","exc_notes":[],"syntax_error":null,"is_cause":true,"frames":[{"filename":"/home/ubuntu/airflow_venv/lib/python3.12/site-packages/elastic_transport/_node/_http_urllib3.py","lineno":167,"name":"perform_request"},{"filename":"/home/ubuntu/airflow_venv/lib/python3.12/site-packages/urllib3/connectionpool.py","lineno":841,"name":"urlopen"},{"filename":"/home/ubuntu/airflow_venv/lib/python3.12/site-packages/urllib3/util/retry.py","lineno":449,"name":"increment"},{"filename":"/home/ubuntu/airflow_venv/lib/python3.12/site-packages/urllib3/util/util.py","lineno":39,"name":"reraise"},{"filename":"/home/ubuntu/airflow_venv/lib/python3.12/site-packages/urllib3/connectionpool.py","lineno":787,"name":"urlopen"},{"filename":"/home/ubuntu/airflow_venv/lib/python3.12/site-packages/urllib3/connectionpool.py","lineno":493,"name":"_make_request"},{"filename":"/home/ubuntu/airflow_venv/lib/python3.12/site-packages/urllib3/connection.py","lineno":445,"name":"request"},{"filename":"/usr/lib/python3.12/http/client.py","lineno":1331,"name":"endheaders"},{"filename":"/usr/lib/python3.12/http/client.py","lineno":1091,"name":"_send_output"},{"filename":"/usr/lib/python3.12/http/client.py","lineno":1035,"name":"send"},{"filename":"/home/ubuntu/airflow_venv/lib/python3.12/site-packages/urllib3/connection.py","lineno":276,"name":"connect"},{"filename":"/home/ubuntu/airflow_venv/lib/python3.12/site-packages/urllib3/connection.py","lineno":213,"name":"_new_conn"}]},{"exc_type":"ConnectionRefusedError","exc_value":"[Errno 111] Connection refused","exc_notes":[],"syntax_error":null,"is_cause":true,"frames":[{"filename":"/home/ubuntu/airflow_venv/lib/python3.12/site-packages/urllib3/connection.py","lineno":198,"name":"_new_conn"},{"filename":"/home/ubuntu/airflow_venv/lib/python3.12/site-packages/urllib3/util/connection.py","lineno":85,"name":"create_connection"},{"filename":"/home/ubuntu/airflow_venv/lib/python3.12/site-packages/urllib3/util/connection.py","lineno":73,"name":"create_connection"}]}]}
{"timestamp":"2025-05-28T01:26:16.706453","level":"info","event":"POST http://localhost:9200/news_raw/_doc [status:N/A duration:0.000s]","logger":"elastic_transport.transport"}
{"timestamp":"2025-05-28T01:26:16.706549","level":"warning","event":"Node <Urllib3HttpNode(http://localhost:9200)> has failed for 3 times in a row, putting on 4 second timeout","logger":"elastic_transport.node_pool"}
{"timestamp":"2025-05-28T01:26:16.706649","level":"warning","event":"Retrying request after failure (attempt 2 of 3)","logger":"elastic_transport.transport","error_detail":[{"exc_type":"ConnectionError","exc_value":"Connection error caused by: NewConnectionError(<urllib3.connection.HTTPConnection object at 0x75beadee0dd0>: Failed to establish a new connection: [Errno 111] Connection refused)","exc_notes":[],"syntax_error":null,"is_cause":false,"frames":[{"filename":"/home/ubuntu/airflow_venv/lib/python3.12/site-packages/elastic_transport/_transport.py","lineno":342,"name":"perform_request"},{"filename":"/home/ubuntu/airflow_venv/lib/python3.12/site-packages/elastic_transport/_node/_http_urllib3.py","lineno":202,"name":"perform_request"}]},{"exc_type":"NewConnectionError","exc_value":"<urllib3.connection.HTTPConnection object at 0x75beadee0dd0>: Failed to establish a new connection: [Errno 111] Connection refused","exc_notes":[],"syntax_error":null,"is_cause":true,"frames":[{"filename":"/home/ubuntu/airflow_venv/lib/python3.12/site-packages/elastic_transport/_node/_http_urllib3.py","lineno":167,"name":"perform_request"},{"filename":"/home/ubuntu/airflow_venv/lib/python3.12/site-packages/urllib3/connectionpool.py","lineno":841,"name":"urlopen"},{"filename":"/home/ubuntu/airflow_venv/lib/python3.12/site-packages/urllib3/util/retry.py","lineno":449,"name":"increment"},{"filename":"/home/ubuntu/airflow_venv/lib/python3.12/site-packages/urllib3/util/util.py","lineno":39,"name":"reraise"},{"filename":"/home/ubuntu/airflow_venv/lib/python3.12/site-packages/urllib3/connectionpool.py","lineno":787,"name":"urlopen"},{"filename":"/home/ubuntu/airflow_venv/lib/python3.12/site-packages/urllib3/connectionpool.py","lineno":493,"name":"_make_request"},{"filename":"/home/ubuntu/airflow_venv/lib/python3.12/site-packages/urllib3/connection.py","lineno":445,"name":"request"},{"filename":"/usr/lib/python3.12/http/client.py","lineno":1331,"name":"endheaders"},{"filename":"/usr/lib/python3.12/http/client.py","lineno":1091,"name":"_send_output"},{"filename":"/usr/lib/python3.12/http/client.py","lineno":1035,"name":"send"},{"filename":"/home/ubuntu/airflow_venv/lib/python3.12/site-packages/urllib3/connection.py","lineno":276,"name":"connect"},{"filename":"/home/ubuntu/airflow_venv/lib/python3.12/site-packages/urllib3/connection.py","lineno":213,"name":"_new_conn"}]},{"exc_type":"ConnectionRefusedError","exc_value":"[Errno 111] Connection refused","exc_notes":[],"syntax_error":null,"is_cause":true,"frames":[{"filename":"/home/ubuntu/airflow_venv/lib/python3.12/site-packages/urllib3/connection.py","lineno":198,"name":"_new_conn"},{"filename":"/home/ubuntu/airflow_venv/lib/python3.12/site-packages/urllib3/util/connection.py","lineno":85,"name":"create_connection"},{"filename":"/home/ubuntu/airflow_venv/lib/python3.12/site-packages/urllib3/util/connection.py","lineno":73,"name":"create_connection"}]}]}
{"timestamp":"2025-05-28T01:26:16.707217","level":"info","event":"POST http://localhost:9200/news_raw/_doc [status:N/A duration:0.000s]","logger":"elastic_transport.transport"}
{"timestamp":"2025-05-28T01:26:16.707307","level":"warning","event":"Node <Urllib3HttpNode(http://localhost:9200)> has failed for 4 times in a row, putting on 8 second timeout","logger":"elastic_transport.node_pool"}
{"timestamp":"2025-05-28T01:26:16.707443","level":"error","event":"Task failed with exception","logger":"task","error_detail":[{"exc_type":"ConnectionError","exc_value":"Connection error caused by: ConnectionError(Connection error caused by: NewConnectionError(<urllib3.connection.HTTPConnection object at 0x75beadee08c0>: Failed to establish a new connection: [Errno 111] Connection refused))","exc_notes":[],"syntax_error":null,"is_cause":false,"frames":[{"filename":"/home/ubuntu/airflow_venv/lib/python3.12/site-packages/airflow/sdk/execution_time/task_runner.py","lineno":838,"name":"run"},{"filename":"/home/ubuntu/airflow_venv/lib/python3.12/site-packages/airflow/sdk/execution_time/task_runner.py","lineno":1130,"name":"_execute_task"},{"filename":"/home/ubuntu/airflow_venv/lib/python3.12/site-packages/airflow/sdk/bases/operator.py","lineno":408,"name":"wrapper"},{"filename":"/home/ubuntu/airflow_venv/lib/python3.12/site-packages/airflow/sdk/bases/decorator.py","lineno":251,"name":"execute"},{"filename":"/home/ubuntu/airflow_venv/lib/python3.12/site-packages/airflow/sdk/bases/operator.py","lineno":408,"name":"wrapper"},{"filename":"/home/ubuntu/airflow_venv/lib/python3.12/site-packages/airflow/providers/standard/operators/python.py","lineno":216,"name":"execute"},{"filename":"/home/ubuntu/airflow_venv/lib/python3.12/site-packages/airflow/providers/standard/operators/python.py","lineno":239,"name":"execute_callable"},{"filename":"/home/ubuntu/airflow_venv/lib/python3.12/site-packages/airflow/sdk/execution_time/callback_runner.py","lineno":81,"name":"run"},{"filename":"/home/ubuntu/airflow/dags/sentiment_fetch_dag.py","lineno":90,"name":"save_to_elasticsearch"},{"filename":"/home/ubuntu/airflow_venv/lib/python3.12/site-packages/elasticsearch/_sync/client/utils.py","lineno":452,"name":"wrapped"},{"filename":"/home/ubuntu/airflow_venv/lib/python3.12/site-packages/elasticsearch/_sync/client/__init__.py","lineno":3043,"name":"index"},{"filename":"/home/ubuntu/airflow_venv/lib/python3.12/site-packages/elasticsearch/_sync/client/_base.py","lineno":271,"name":"perform_request"},{"filename":"/home/ubuntu/airflow_venv/lib/python3.12/site-packages/elasticsearch/_sync/client/_base.py","lineno":315,"name":"_perform_request"},{"filename":"/home/ubuntu/airflow_venv/lib/python3.12/site-packages/elastic_transport/_transport.py","lineno":342,"name":"perform_request"},{"filename":"/home/ubuntu/airflow_venv/lib/python3.12/site-packages/elastic_transport/_node/_http_urllib3.py","lineno":202,"name":"perform_request"}]},{"exc_type":"NewConnectionError","exc_value":"<urllib3.connection.HTTPConnection object at 0x75beadee1250>: Failed to establish a new connection: [Errno 111] Connection refused","exc_notes":[],"syntax_error":null,"is_cause":true,"frames":[{"filename":"/home/ubuntu/airflow_venv/lib/python3.12/site-packages/elastic_transport/_node/_http_urllib3.py","lineno":167,"name":"perform_request"},{"filename":"/home/ubuntu/airflow_venv/lib/python3.12/site-packages/urllib3/connectionpool.py","lineno":841,"name":"urlopen"},{"filename":"/home/ubuntu/airflow_venv/lib/python3.12/site-packages/urllib3/util/retry.py","lineno":449,"name":"increment"},{"filename":"/home/ubuntu/airflow_venv/lib/python3.12/site-packages/urllib3/util/util.py","lineno":39,"name":"reraise"},{"filename":"/home/ubuntu/airflow_venv/lib/python3.12/site-packages/urllib3/connectionpool.py","lineno":787,"name":"urlopen"},{"filename":"/home/ubuntu/airflow_venv/lib/python3.12/site-packages/urllib3/connectionpool.py","lineno":493,"name":"_make_request"},{"filename":"/home/ubuntu/airflow_venv/lib/python3.12/site-packages/urllib3/connection.py","lineno":445,"name":"request"},{"filename":"/usr/lib/python3.12/http/client.py","lineno":1331,"name":"endheaders"},{"filename":"/usr/lib/python3.12/http/client.py","lineno":1091,"name":"_send_output"},{"filename":"/usr/lib/python3.12/http/client.py","lineno":1035,"name":"send"},{"filename":"/home/ubuntu/airflow_venv/lib/python3.12/site-packages/urllib3/connection.py","lineno":276,"name":"connect"},{"filename":"/home/ubuntu/airflow_venv/lib/python3.12/site-packages/urllib3/connection.py","lineno":213,"name":"_new_conn"}]},{"exc_type":"ConnectionRefusedError","exc_value":"[Errno 111] Connection refused","exc_notes":[],"syntax_error":null,"is_cause":true,"frames":[{"filename":"/home/ubuntu/airflow_venv/lib/python3.12/site-packages/urllib3/connection.py","lineno":198,"name":"_new_conn"},{"filename":"/home/ubuntu/airflow_venv/lib/python3.12/site-packages/urllib3/util/connection.py","lineno":85,"name":"create_connection"},{"filename":"/home/ubuntu/airflow_venv/lib/python3.12/site-packages/urllib3/util/connection.py","lineno":73,"name":"create_connection"}]}]}
